Workbook

Sheet Dashboard
B2: 📊 E-COMMERCE SALES PERFORMANCE DASHBOARD | 2026
B5: 🔎 FILTERS (Slicers) | E5: 💰 TOTAL REVENUE | H5: 🛒 TOTAL ORDERS | K5: 📦 QUANTITY SOLD | N5: 🏷 AVG ORDER VALUE
E6: =SUMIFS(Clean_Data!$F$2:$F$101,Clean_Data!$H$2:$H$101,"Valid",Clean_Data!$C$2:$C$101,Chart_Data!$B$2,Clean_Data!$D$2:$D$101,Chart_Data!$B$3,Clean_Data!$G$2:$G$101,Chart_Data!$B$4) | H6: =COUNTIFS(Clean_Data!$H$2:$H$101,"Valid",Clean_Data!$C$2:$C$101,Chart_Data!$B$2,Clean_Data!$D$2:$D$101,Chart_Data!$B$3,Clean_Data!$G$2:$G$101,Chart_Data!$B$4) | K6: =SUMIFS(Clean_Data!$E$2:$E$101,Clean_Data!$H$2:$H$101,"Valid",Clean_Data!$C$2:$C$101,Chart_Data!$B$2,Clean_Data!$D$2:$D$101,Chart_Data!$B$3,Clean_Data!$G$2:$G$101,Chart_Data!$B$4) | N6: =IFERROR(SUMIFS(Clean_Data!$F$2:$F$101,Clean_Data!$H$2:$H$101,"Valid",Clean_Data!$C$2:$C$101,Chart_Data!$B$2,Clean_Data!$D$2:$D$101,Chart_Data!$B$3,Clean_Data!$G$2:$G$101,Chart_Data!$B$4)/COUNTIFS(Clean_Data!$H$2:$H$101,"Valid",Clean_Data!$C$2:$C$101,Chart_Data!$B$2,Clean_Data!$D$2:$D$101,Chart_Data!$B$3,Clean_Data!$G$2:$G$101,Chart_Data!$B$4),0)
B7: Region ▼
B8: All
B10: Category ▼
B11: All
B13: Month ▼
B14: All
B17: टीप: Dropdown मधून निवडा. सगळे KPIs आणि charts आपोआप बदलतील. Reset करण्यासाठी तिन्ही मध्ये 'All' निवडा.

Sheet Project_Guide
A1: Project Guide (Explain करण्यासाठी)
A3: Project काय आहे | B3: E-commerce कंपनीच्या 100 orders चा छोटा data (Jan-Sep 2026). त्यावर cleaning, pivot summary आणि interactive dashboard बनवला आहे.
A4: Business प्रश्न | B4: कोणत्या Region आणि Category मधून जास्त Revenue येतो? कोणत्या महिन्यात sales वाढला? Average Order Value किती आहे?
A5: 1. Raw_Data | B5: मूळ अस्वच्छ data: extra spaces, चुकीचे CAPITAL/small letters, 4 duplicate orders, 2 रिकामे Revenue.
A6: 2. Clean_Data | B6: Formulas वापरून cleaning: TRIM, PROPER, COUNTIF, IF. Status column मध्ये Valid / Duplicate / Missing दिसते. हा Excel Table आहे.
A7: 3. Pivot_Tables | B7: Region, Category, Month नुसार summary आणि Region x Category cross-tab (SUMIFS / COUNTIFS).
A8: 4. Chart_Data | B8: Charts ला लागणारा data. Dropdown बदलला की आपोआप बदलतो.
A9: 5. Dashboard | B9: डावीकडे 3 filters (Region, Category, Month), वर 4 KPI cards आणि 4 charts. Filter बदला, सगळे बदलते.
A10: Tip: खरा Slicer | B10: Clean_Data मध्ये table वर click -> Insert -> Slicer -> Region, Category निवडा. PivotTable साठी Insert -> PivotTable.
A11: Formulas वापरले | B11: SUMIFS, COUNTIFS, IFERROR, TRIM, PROPER, COUNTIF, CHOOSE, SUM.

Sheet Raw_Data
A1: Order ID | B1: Date | C1: Region | D1: Category | E1: Quantity | F1: Revenue | H1: Note: ही Raw (अस्वच्छ) data आहे - extra spaces, चुकीचे CAPITAL/small letters, 4 duplicate orders आणि 2 रिकामे Revenue मुद्दाम ठेवले आहेत.
A2: EC2001 | B2: 46023 | C2: Central | D2: Home Decor | E2: 3 | F2: 26100
A3: EC2002 | B3: 46028 | C3: East | D3: Electronics | E3: 4 | F3: 159600
A4: EC2003 | B4: 46029 | C4: NORTH | D4: HOME DECOR | E4: 3 | F4: 22200
A5: EC2004 | B5: 46031 | C5: South | D5: Electronics | E5: 3 | F5: 105000
A6: EC2005 | B6: 46034 | C6: east | D6: Electronics | E6: 2 | F6: 36400
A7: EC2006 | B7: 46037 | C7: Central | D7: FASHION | E7: 1 | F7: 2600
A8: EC2007 | B8: 46037 | C8: south | D8: Sports | E8: 1 | F8: 5400
A9: EC2008 | B9: 46039 | C9: North | D9: home decor | E9: 1 | F9: 7100
A10: EC2009 | B10: 46049 | C10: South | D10: beauty | E10: 4 | F10: 8400
A11: EC2010 | B11: 46057 | C11: east | D11: Electronics | E11: 1 | F11: 22000
A12: EC2011 | B12: 46060 | C12: north | D12: sports | E12: 2 | F12: 13400
A13: EC2012 | B13: 46060 | C13: West | D13: Electronics | E13: 1 | F13: 21700
... A15: EC2014 | B15: 46061 | C15: North | D15: BEAUTY | E15: 1 | F15: 1800
A16: EC2015 | B16: 46064 | C16: South | D16: Electronics | E16: 1
A17: EC2016 | B17: 46065 | C17: west | D17: Sports | E17: 1 | F17: 3700
A18: EC2017 | B18: 46066 | C18: Central | D18: Beauty | E18: 1 | F18: 2200
A19: EC2018 | B19: 46067 | C19: Central | D19: Beauty | E19: 1 | F19: 1400
A20: EC2019 | B20: 46067 | C20: South | D20: BEAUTY | E20: 4 | F20: 4000
A21: EC2020 | B21: 46067 | C21: Central | D21: Home Decor | E21: 3 | F21: 10800
A22: EC2021 | B22: 46067 | C22: West | D22: Fashion | E22: 4 | F22: 12000
A23: EC2022 | B23: 46069 | C23: south | D23: Sports | E23: 1 | F23: 6100
A24: EC2023 | B24: 46073 | C24: South | D24: Electronics | E24: 2 | F24: 47800
A25: EC2024 | B25: 46074 | C25: South | D25: electronics | E25: 2 | F25: 44000
A26: EC2025 | B26: 46078 | C26: south | D26: beauty | E26: 1 | F26: 1700
A27: EC2026 | B27: 46081 | C27: south | D27: SPORTS | E27: 1 | F27: 6200
A28: EC2027 | B28: 46085 | C28: Central | D28: Beauty | E28: 1 | F28: 1200
... A61: EC2060 | B61: 46171 | C61: west | D61: SPORTS | E61: 2 | F61: 11000
A62: EC2061 | B62: 46173 | C62: South | D62: Beauty | E62: 1
A63: EC2062 | B63: 46192 | C63: South | D63: Beauty | E63: 4 | F63: 9200
A64: EC2063 | B64: 46195 | C64: central | D64: ELECTRONICS | E64: 3 | F64: 89400
A65: EC2064 | B65: 46198 | C65: SOUTH | D65: SPORTS | E65: 4 | F65: 14000
A66: EC2065 | B66: 46201 | C66: South | D66: Sports | E66: 1 | F66: 1500
A67: EC2066 | B67: 46204 | C67: East | D67: Home Decor | E67: 1 | F67: 6800
A68: EC2067 | B68: 46206 | C68: west | D68: Home Decor | E68: 1 | F68: 1700
A69: EC2068 | B69: 46211 | C69: North | D69: Sports | E69: 2 | F69: 4000
A70: EC2069 | B70: 46211 | C70: North | D70: Electronics | E70: 2 | F70: 60800
A71: EC2070 | B71: 46211 | C71: West | D71: Home Decor | E71: 2 | F71: 14200
A72: EC2071 | B72: 46217 | C72: Central | D72: Sports | E72: 1 | F72: 6200
A73: EC2072 | B73: 46219 | C73: East | D73: Electronics | E73: 4 | F73: 142400
...

Sheet Clean_Data
A1: Order ID | B1: Date | C1: Region | D1: Category | E1: Quantity | F1: Revenue | G1: Month | H1: Status | J1: Data Cleaning Summary
A2: =TRIM(Raw_Data!A2) | B2: =IF(Raw_Data!B2="","",Raw_Data!B2) | C2: =PROPER(TRIM(Raw_Data!C2)) | D2: =PROPER(TRIM(Raw_Data!D2)) | E2: =IF(Raw_Data!E2="","",Raw_Data!E2) | F2: =IF(Raw_Data!F2="",0,Raw_Data!F2) | G2: =IF(B2="","",CHOOSE(MONTH(B2),"Jan","Feb","Mar","Apr","May","Jun","Jul","Aug","Sep","Oct","Nov","Dec")) | H2: =IF(OR(B2="",E2="",Raw_Data!F2=""),"Missing",IF(COUNTIF($A$2:A2,A2)>1,"Duplicate","Valid")) | J2: Total raw rows | K2: =COUNTA(A2:A101)
A3: =TRIM(Raw_Data!A3) | B3: =IF(Raw_Data!B3="","",Raw_Data!B3) | C3: =PROPER(TRIM(Raw_Data!C3)) | D3: =PROPER(TRIM(Raw_Data!D3)) | E3: =IF(Raw_Data!E3="","",Raw_Data!E3) | F3: =IF(Raw_Data!F3="",0,Raw_Data!F3) | G3: =IF(B3="","",CHOOSE(MONTH(B3),"Jan","Feb","Mar","Apr","May","Jun","Jul","Aug","Sep","Oct","Nov","Dec")) | H3: =IF(OR(B3="",E3="",Raw_Data!F3=""),"Missing",IF(COUNTIF($A$2:A3,A3)>1,"Duplicate","Valid")) | J3: Valid rows | K3: =COUNTIF(H2:H101,"Valid")
A4: =TRIM(Raw_Data!A4) | B4: =IF(Raw_Data!B4="","",Raw_Data!B4) | C4: =PROPER(TRIM(Raw_Data!C4)) | D4: =PROPER(TRIM(Raw_Data!D4)) | E4: =IF(Raw_Data!E4="","",Raw_Data!E4) | F4: =IF(Raw_Data!F4="",0,Raw_Data!F4) | G4: =IF(B4="","",CHOOSE(MONTH(B4),"Jan","Feb","Mar","Apr","May","Jun","Jul","Aug","Sep","Oct","Nov","Dec")) | H4: =IF(OR(B4="",E4="",Raw_Data!F4=""),"Missing",IF(COUNTIF($A$2:A4,A4)>1,"Duplicate","Valid")) | J4: Duplicate rows | K4: =COUNTIF(H2:H101,"Duplicate")
A5: =TRIM(Raw_Data!A5) | B5: =IF(Raw_Data!B5="","",Raw_Data!B5) | C5: =PROPER(TRIM(Raw_Data!C5)) | D5: =PROPER(TRIM(Raw_Data!D5)) | E5: =IF(Raw_Data!E5="","",Raw_Data!E5) | F5: =IF(Raw_Data!F5="",0,Raw_Data!F5) | G5: =IF(B5="","",CHOOSE(MONTH(B5),"Jan","Feb","Mar","Apr","May","Jun","Jul","Aug","Sep","Oct","Nov","Dec")) | H5: =IF(OR(B5="",E5="",Raw_Data!F5=""),"Missing",IF(COUNTIF($A$2:A5,A5)>1,"Duplicate","Valid")) | J5: Rows with missing data | K5: =COUNTIF(H2:H101,"Missing")
A6: =TRIM(Raw_Data!A6) | B6: =IF(Raw_Data!B6="","",Raw_Data!B6) | C6: =PROPER(TRIM(Raw_Data!C6)) | D6: =PROPER(TRIM(Raw_Data!D6)) | E6: =IF(Raw_Data!E6="","",Raw_Data!E6) | F6: =IF(Raw_Data!F6="",0,Raw_Data!F6) | G6: =IF(B6="","",CHOOSE(MONTH(B6),"Jan","Feb","Mar","Apr","May","Jun","Jul","Aug","Sep","Oct","Nov","Dec")) | H6: =IF(OR(B6="",E6="",Raw_Data!F6=""),"Missing",IF(COUNTIF($A$2:A6,A6)>1,"Duplicate","Valid"))
A7: =TRIM(Raw_Data!A7) | B7: =IF(Raw_Data!B7="","",Raw_Data!B7) | C7: =PROPER(TRIM(Raw_Data!C7)) | D7: =PROPER(TRIM(Raw_Data!D7)) | E7: =IF(Raw_Data!E7="","",Raw_Data!E7) | F7: =IF(Raw_Data!F7="",0,Raw_Data!F7) | G7: =IF(B7="","",CHOOSE(MONTH(B7),"Jan","Feb","Mar","Apr","May","Jun","Jul","Aug","Sep","Oct","Nov","Dec")) | H7: =IF(OR(B7="",E7="",Raw_Data!F7=""),"Missing",IF(COUNTIF($A$2:A7,A7)>1,"Duplicate","Valid")) | J7: Steps: TRIM (extra space काढणे), PROPER (एकसारखे अक्षर), COUNTIF (duplicate शोधणे), IF (missing शोधणे). Dashboard फक्त 'Valid' rows वापरतो.
A8: =TRIM(Raw_Data!A8) | B8: =IF(Raw_Data!B8="","",Raw_Data!B8) | C8: =PROPER(TRIM(Raw_Data!C8)) | D8: =PROPER(TRIM(Raw_Data!D8)) | E8: =IF(Raw_Data!E8="","",Raw_Data!E8) | F8: =IF(Raw_Data!F8="",0,Raw_Data!F8) | G8: =IF(B8="","",CHOOSE(MONTH(B8),"Jan","Feb","Mar","Apr","May","Jun","Jul","Aug","Sep","Oct","Nov","Dec")) | H8: =IF(OR(B8="",E8="",Raw_Data!F8=""),"Missing",IF(COUNTIF($A$2:A8,A8)>1,"Duplicate","Valid"))
A9: =TRIM(Raw_Data!A9) | B9: =IF(Raw_Data!B9="","",Raw_Data!B9) | C9: =PROPER(TRIM(Raw_Data!C9)) | D9: =PROPER(TRIM(Raw_Data!D9)) | E9: =IF(Raw_Data!E9="","",Raw_Data!E9) | F9: =IF(Raw_Data!F9="",0,Raw_Data!F9) | G9: =IF(B9="","",CHOOSE(MONTH(B9),"Jan","Feb","Mar","Apr","May","Jun","Jul","Aug","Sep","Oct","Nov","Dec")) | H9: =IF(OR(B9="",E9="",Raw_Data!F9=""),"Missing",IF(COUNTIF($A$2:A9,A9)>1,"Duplicate","Valid"))
A10: =TRIM(Raw_Data!A10) | B10: =IF(Raw_Data!B10="","",Raw_Data!B10) | C10: =PROPER(TRIM(Raw_Data!C10)) | D10: =PROPER(TRIM(Raw_Data!D10)) | E10: =IF(Raw_Data!E10="","",Raw_Data!E10) | F10: =IF(Raw_Data!F10="",0,Raw_Data!F10) | G10: =IF(B10="","",CHOOSE(MONTH(B10),"Jan","Feb","Mar","Apr","May","Jun","Jul","Aug","Sep","Oct","Nov","Dec")) | H10: =IF(OR(B10="",E10="",Raw_Data!F10=""),"Missing",IF(COUNTIF($A$2:A10,A10)>1,"Duplicate","Valid"))
A11: =TRIM(Raw_Data!A11) | B11: =IF(Raw_Data!B11="","",Raw_Data!B11) | C11: =PROPER(TRIM(Raw_Data!C11)) | D11: =PROPER(TRIM(Raw_Data!D11)) | E11: =IF(Raw_Data!E11="","",Raw_Data!E11) | F11: =IF(Raw_Data!F11="",0,Raw_Data!F11) | G11: =IF(B11="","",CHOOSE(MONTH(B11),"Jan","Feb","Mar","Apr","May","Jun","Jul","Aug","Sep","Oct","Nov","Dec")) | H11: =IF(OR(B11="",E11="",Raw_Data!F11=""),"Missing",IF(COUNTIF($A$2:A11,A11)>1,"Duplicate","Valid"))
A12: =TRIM(Raw_Data!A12) | B12: =IF(Raw_Data!B12="","",Raw_Data!B12) | C12: =PROPER(TRIM(Raw_Data!C12)) | D12: =PROPER(TRIM(Raw_Data!D12)) | E12: =IF(Raw_Data!E12="","",Raw_Data!E12) | F12: =IF(Raw_Data!F12="",0,Raw_Data!F12) | G12: =IF(B12="","",CHOOSE(MONTH(B12),"Jan","Feb","Mar","Apr","May","Jun","Jul","Aug","Sep","Oct","Nov","Dec")) | H12: =IF(OR(B12="",E12="",Raw_Data!F12=""),"Missing",IF(COUNTIF($A$2:A12,A12)>1,"Duplicate","Valid"))
A13: =TRIM(Raw_Data!A13) | B13: =IF(Raw_Data!B13="","",Raw_Data!B13) | C13: =PROPER(TRIM(Raw_Data!C13)) | D13: =PROPER(TRIM(Raw_Data!D13)) | E13: =IF(Raw_Data!E13="","",Raw_Data!E13) | F13: =IF(Raw_Data!F13="",0,Raw_Data!F13) | G13: =IF(B13="","",CHOOSE(MONTH(B13),"Jan","Feb","Mar","Apr","May","Jun","Jul","Aug","Sep","Oct","Nov","Dec")) | H13: =IF(OR(B13="",E13="",Raw_Data!F13=""),"Missing",IF(COUNTIF($A$2:A13,A13)>1,"Duplicate","Valid"))
A14: =TRIM(Raw_Data!A14) | B14: =IF(Raw_Data!B14="","",Raw_Data!B14) | C14: =PROPER(TRIM(Raw_Data!C14)) | D14: =PROPER(TRIM(Raw_Data!D14)) | E14: =IF(Raw_Data!E14="","",Raw_Data!E14) | F14: =IF(Raw_Data!F14="",0,Raw_Data!F14) | G14: =IF(B14="","",CHOOSE(MONTH(B14),"Jan","Feb","Mar","Apr","May","Jun","Jul","Aug","Sep","Oct","Nov","Dec")) | H14: =IF(OR(B14="",E14="",Raw_Data!F14=""),"Missing",IF(COUNTIF($A$2:A14,A14)>1,"Duplicate","Valid"))
A15: =TRIM(Raw_Data!A15) | B15: =IF(Raw_Data!B15="","",Raw_Data!B15) | C15: =PROPER(TRIM(Raw_Data!C15)) | D15: =PROPER(TRIM(Raw_Data!D15)) | E15: =IF(Raw_Data!E15="","",Raw_Data!E15) | F15: =IF(Raw_Data!F15="",0,Raw_Data!F15) | G15: =IF(B15="","",CHOOSE(MONTH(B15),"Jan","Feb","Mar","Apr","May","Jun","Jul","Aug","Sep","Oct","Nov","Dec")) | H15: =IF(OR(B15="",E15="",Raw_Data!F15=""),"Missing",IF(COUNTIF($A$2:A15,A15)>1,"Duplicate","Valid"))
A16: =TRIM(Raw_Data!A16) | B16: =IF(Raw_Data!B16="","",Raw_Data!B16) | C16: =PROPER(TRIM(Raw_Data!C16)) | D16: =PROPER(TRIM(Raw_Data!D16)) | E16: =IF(Raw_Data!E16="","",Raw_Data!E16) | F16: =IF(Raw_Data!F16="",0,Raw_Data!F16) | G16: =IF(B16="","",CHOOSE(MONTH(B16),"Jan","Feb","Mar","Apr","May","Jun","Jul","Aug","Sep","Oct","Nov","Dec")) | H16: =IF(OR(B16="",E16="",Raw_Data!F16=""),"Missing",IF(COUNTIF($A$2:A16,A16)>1,"Duplicate","Valid"))
A17: =TRIM(Raw_Data!A17) | B17: =IF(Raw_Data!B17="","",Raw_Data!B17) | C17: =PROPER(TRIM(Raw_Data!C17)) | D17: =PROPER(TRIM(Raw_Data!D17)) | E17: =IF(Raw_Data!E17="","",Raw_Data!E17) | F17: =IF(Raw_Data!F17="",0,Raw_Data!F17) | G17: =IF(B17="","",CHOOSE(MONTH(B17),"Jan","Feb","Mar","Apr","May","Jun","Jul","Aug","Sep","Oct","Nov","Dec")) | H17: =IF(OR(B17="",E17="",Raw_Data!F17=""),"Missing",IF(COUNTIF($A$2:A17,A17)>1,"Duplicate","Valid"))
A18: =TRIM(Raw_Data!A18) | B18: =IF(Raw_Data!B18="","",Raw_Data!B18) | C18: =PROPER(TRIM(Raw_Data!C18)) | D18: =PROPER(TRIM(Raw_Data!D18)) | E18: =IF(Raw_Data!E18="","",Raw_Data!E18) | F18: =IF(Raw_Data!F18="",0,Raw_Data!F18) | G18: =IF(B18="","",CHOOSE(MONTH(B18),"Jan","Feb","Mar","Apr","May","Jun","Jul","Aug","Sep","Oct","Nov","Dec")) | H18: =IF(OR(B18="",E18="",Raw_Data!F18=""),"Missing",IF(COUNTIF($A$2:A18,A18)>1,"Duplicate","Valid"))
A19: =TRIM(Raw_Data!A19) | B19: =IF(Raw_Data!B19="","",Raw_Data!B19) | C19: =PROPER(TRIM(Raw_Data!C19)) | D19: =PROPER(TRIM(Raw_Data!D19)) | E19: =IF(Raw_Data!E19="","",Raw_Data!E19) | F19: =IF(Raw_Data!F19="",0,Raw_Data!F19) | G19: =IF(B19="","",CHOOSE(MONTH(B19),"Jan","Feb","Mar","Apr","May","Jun","Jul","Aug","Sep","Oct","Nov","Dec")) | H19: =IF(OR(B19="",E19="",Raw_Data!F19=""),"Missing",IF(COUNTIF($A$2:A19,A19)>1,"Duplicate","Valid"))
... A101: =TRIM(Raw_Data!A101) | B101: =IF(Raw_Data!B101="","",Raw_Data!B101) | C101: =PROPER(TRIM(Raw_Data!C101)) | D101: =PROPER(TRIM(Raw_Data!D101)) | E101: =IF(Raw_Data!E101="","",Raw_Data!E101) | F101: =IF(Raw_Data!F101="",0,Raw_Data!F101) | G101: =IF(B101="","",CHOOSE(MONTH(B101),"Jan","Feb","Mar","Apr","May","Jun","Jul","Aug","Sep","Oct","Nov","Dec")) | H101: =IF(OR(B101="",E101="",Raw_Data!F101=""),"Missing",IF(COUNTIF($A$2:A101,A101)>1,"Duplicate","Valid"))

Sheet Pivot_Tables
A1: Pivot Tables (Summary) - सर्व Valid data वर आधारित
A3: 1) Region नुसार | H3: 3) Month नुसार
A4: Name | B4: Revenue | C4: Orders | D4: Quantity | E4: Avg Order | H4: Name | I4: Revenue | J4: Orders | K4: Quantity | L4: Avg Order
A5: Central | B5: =SUMIFS(Clean_Data!$F$2:$F$101,Clean_Data!$H$2:$H$101,"Valid",Clean_Data!$C$2:$C$101,A5) | C5: =COUNTIFS(Clean_Data!$H$2:$H$101,"Valid",Clean_Data!$C$2:$C$101,A5) | D5: =SUMIFS(Clean_Data!$E$2:$E$101,Clean_Data!$H$2:$H$101,"Valid",Clean_Data!$C$2:$C$101,A5) | E5: =IFERROR(B5/C5,0) | H5: Jan | I5: =SUMIFS(Clean_Data!$F$2:$F$101,Clean_Data!$H$2:$H$101,"Valid",Clean_Data!$G$2:$G$101,H5) | J5: =COUNTIFS(Clean_Data!$H$2:$H$101,"Valid",Clean_Data!$G$2:$G$101,H5) | K5: =SUMIFS(Clean_Data!$E$2:$E$101,Clean_Data!$H$2:$H$101,"Valid",Clean_Data!$G$2:$G$101,H5) | L5: =IFERROR(I5/J5,0)
A6: East | B6: =SUMIFS(Clean_Data!$F$2:$F$101,Clean_Data!$H$2:$H$101,"Valid",Clean_Data!$C$2:$C$101,A6) | C6: =COUNTIFS(Clean_Data!$H$2:$H$101,"Valid",Clean_Data!$C$2:$C$101,A6) | D6: =SUMIFS(Clean_Data!$E$2:$E$101,Clean_Data!$H$2:$H$101,"Valid",Clean_Data!$C$2:$C$101,A6) | E6: =IFERROR(B6/C6,0) | H6: Feb | I6: =SUMIFS(Clean_Data!$F$2:$F$101,Clean_Data!$H$2:$H$101,"Valid",Clean_Data!$G$2:$G$101,H6) | J6: =COUNTIFS(Clean_Data!$H$2:$H$101,"Valid",Clean_Data!$G$2:$G$101,H6) | K6: =SUMIFS(Clean_Data!$E$2:$E$101,Clean_Data!$H$2:$H$101,"Valid",Clean_Data!$G$2:$G$101,H6) | L6: =IFERROR(I6/J6,0)
A7: North | B7: =SUMIFS(Clean_Data!$F$2:$F$101,Clean_Data!$H$2:$H$101,"Valid",Clean_Data!$C$2:$C$101,A7) | C7: =COUNTIFS(Clean_Data!$H$2:$H$101,"Valid",Clean_Data!$C$2:$C$101,A7) | D7: =SUMIFS(Clean_Data!$E$2:$E$101,Clean_Data!$H$2:$H$101,"Valid",Clean_Data!$C$2:$C$101,A7) | E7: =IFERROR(B7/C7,0) | H7: Mar | I7: =SUMIFS(Clean_Data!$F$2:$F$101,Clean_Data!$H$2:$H$101,"Valid",Clean_Data!$G$2:$G$101,H7) | J7: =COUNTIFS(Clean_Data!$H$2:$H$101,"Valid",Clean_Data!$G$2:$G$101,H7) | K7: =SUMIFS(Clean_Data!$E$2:$E$101,Clean_Data!$H$2:$H$101,"Valid",Clean_Data!$G$2:$G$101,H7) | L7: =IFERROR(I7/J7,0)
A8: South | B8: =SUMIFS(Clean_Data!$F$2:$F$101,Clean_Data!$H$2:$H$101,"Valid",Clean_Data!$C$2:$C$101,A8) | C8: =COUNTIFS(Clean_Data!$H$2:$H$101,"Valid",Clean_Data!$C$2:$C$101,A8) | D8: =SUMIFS(Clean_Data!$E$2:$E$101,Clean_Data!$H$2:$H$101,"Valid",Clean_Data!$C$2:$C$101,A8) | E8: =IFERROR(B8/C8,0) | H8: Apr | I8: =SUMIFS(Clean_Data!$F$2:$F$101,Clean_Data!$H$2:$H$101,"Valid",Clean_Data!$G$2:$G$101,H8) | J8: =COUNTIFS(Clean_Data!$H$2:$H$101,"Valid",Clean_Data!$G$2:$G$101,H8) | K8: =SUMIFS(Clean_Data!$E$2:$E$101,Clean_Data!$H$2:$H$101,"Valid",Clean_Data!$G$2:$G$101,H8) | L8: =IFERROR(I8/J8,0)
A9: West | B9: =SUMIFS(Clean_Data!$F$2:$F$101,Clean_Data!$H$2:$H$101,"Valid",Clean_Data!$C$2:$C$101,A9) | C9: =COUNTIFS(Clean_Data!$H$2:$H$101,"Valid",Clean_Data!$C$2:$C$101,A9) | D9: =SUMIFS(Clean_Data!$E$2:$E$101,Clean_Data!$H$2:$H$101,"Valid",Clean_Data!$C$2:$C$101,A9) | E9: =IFERROR(B9/C9,0) | H9: May | I9: =SUMIFS(Clean_Data!$F$2:$F$101,Clean_Data!$H$2:$H$101,"Valid",Clean_Data!$G$2:$G$101,H9) | J9: =COUNTIFS(Clean_Data!$H$2:$H$101,"Valid",Clean_Data!$G$2:$G$101,H9) | K9: =SUMIFS(Clean_Data!$E$2:$E$101,Clean_Data!$H$2:$H$101,"Valid",Clean_Data!$G$2:$G$101,H9) | L9: =IFERROR(I9/J9,0)
A10: Grand Total | B10: =SUM(B5:B9) | C10: =SUM(C5:C9) | D10: =SUM(D5:D9) | E10: =IFERROR(B10/C10,0) | H10: Jun | I10: =SUMIFS(Clean_Data!$F$2:$F$101,Clean_Data!$H$2:$H$101,"Valid",Clean_Data!$G$2:$G$101,H10) | J10: =COUNTIFS(Clean_Data!$H$2:$H$101,"Valid",Clean_Data!$G$2:$G$101,H10) | K10: =SUMIFS(Clean_Data!$E$2:$E$101,Clean_Data!$H$2:$H$101,"Valid",Clean_Data!$G$2:$G$101,H10) | L10: =IFERROR(I10/J10,0)
H11: Jul | I11: =SUMIFS(Clean_Data!$F$2:$F$101,Clean_Data!$H$2:$H$101,"Valid",Clean_Data!$G$2:$G$101,H11) | J11: =COUNTIFS(Clean_Data!$H$2:$H$101,"Valid",Clean_Data!$G$2:$G$101,H11) | K11: =SUMIFS(Clean_Data!$E$2:$E$101,Clean_Data!$H$2:$H$101,"Valid",Clean_Data!$G$2:$G$101,H11) | L11: =IFERROR(I11/J11,0)
A12: 2) Category नुसार | H12: Aug | I12: =SUMIFS(Clean_Data!$F$2:$F$101,Clean_Data!$H$2:$H$101,"Valid",Clean_Data!$G$2:$G$101,H12) | J12: =COUNTIFS(Clean_Data!$H$2:$H$101,"Valid",Clean_Data!$G$2:$G$101,H12) | K12: =SUMIFS(Clean_Data!$E$2:$E$101,Clean_Data!$H$2:$H$101,"Valid",Clean_Data!$G$2:$G$101,H12) | L12: =IFERROR(I12/J12,0)
A13: Name | B13: Revenue | C13: Orders | D13: Quantity | E13: Avg Order | H13: Sep | I13: =SUMIFS(Clean_Data!$F$2:$F$101,Clean_Data!$H$2:$H$101,"Valid",Clean_Data!$G$2:$G$101,H13) | J13: =COUNTIFS(Clean_Data!$H$2:$H$101,"Valid",Clean_Data!$G$2:$G$101,H13) | K13: =SUMIFS(Clean_Data!$E$2:$E$101,Clean_Data!$H$2:$H$101,"Valid",Clean_Data!$G$2:$G$101,H13) | L13: =IFERROR(I13/J13,0)
A14: Electronics | B14: =SUMIFS(Clean_Data!$F$2:$F$101,Clean_Data!$H$2:$H$101,"Valid",Clean_Data!$D$2:$D$101,A14) | C14: =COUNTIFS(Clean_Data!$H$2:$H$101,"Valid",Clean_Data!$D$2:$D$101,A14) | D14: =SUMIFS(Clean_Data!$E$2:$E$101,Clean_Data!$H$2:$H$101,"Valid",Clean_Data!$D$2:$D$101,A14) | E14: =IFERROR(B14/C14,0) | H14: Grand Total | I14: =SUM(I5:I13) | J14: =SUM(J5:J13) | K14: =SUM(K5:K13) | L14: =IFERROR(I14/J14,0)
A15: Fashion | B15: =SUMIFS(Clean_Data!$F$2:$F$101,Clean_Data!$H$2:$H$101,"Valid",Clean_Data!$D$2:$D$101,A15) | C15: =COUNTIFS(Clean_Data!$H$2:$H$101,"Valid",Clean_Data!$D$2:$D$101,A15) | D15: =SUMIFS(Clean_Data!$E$2:$E$101,Clean_Data!$H$2:$H$101,"Valid",Clean_Data!$D$2:$D$101,A15) | E15: =IFERROR(B15/C15,0)
A16: Home Decor | B16: =SUMIFS(Clean_Data!$F$2:$F$101,Clean_Data!$H$2:$H$101,"Valid",Clean_Data!$D$2:$D$101,A16) | C16: =COUNTIFS(Clean_Data!$H$2:$H$101,"Valid",Clean_Data!$D$2:$D$101,A16) | D16: =SUMIFS(Clean_Data!$E$2:$E$101,Clean_Data!$H$2:$H$101,"Valid",Clean_Data!$D$2:$D$101,A16) | E16: =IFERROR(B16/C16,0)
A17: Beauty | B17: =SUMIFS(Clean_Data!$F$2:$F$101,Clean_Data!$H$2:$H$101,"Valid",Clean_Data!$D$2:$D$101,A17) | C17: =COUNTIFS(Clean_Data!$H$2:$H$101,"Valid",Clean_Data!$D$2:$D$101,A17) | D17: =SUMIFS(Clean_Data!$E$2:$E$101,Clean_Data!$H$2:$H$101,"Valid",Clean_Data!$D$2:$D$101,A17) | E17: =IFERROR(B17/C17,0) | H17: 4) Region x Category (Cross-tab)
A18: Sports | B18: =SUMIFS(Clean_Data!$F$2:$F$101,Clean_Data!$H$2:$H$101,"Valid",Clean_Data!$D$2:$D$101,A18) | C18: =COUNTIFS(Clean_Data!$H$2:$H$101,"Valid",Clean_Data!$D$2:$D$101,A18) | D18: =SUMIFS(Clean_Data!$E$2:$E$101,Clean_Data!$H$2:$H$101,"Valid",Clean_Data!$D$2:$D$101,A18) | E18: =IFERROR(B18/C18,0) | H18: Region | I18: Electronics | J18: Fashion | K18: Home Decor | L18: Beauty | M18: Sports | N18: Total
A19: Grand Total | B19: =SUM(B14:B18) | C19: =SUM(C14:C18) | D19: =SUM(D14:D18) | E19: =IFERROR(B19/C19,0) | H19: Central | I19: =SUMIFS(Clean_Data!$F$2:$F$101,Clean_Data!$H$2:$H$101,"Valid",Clean_Data!$C$2:$C$101,$H19,Clean_Data!$D$2:$D$101,I$18) | J19: =SUMIFS(Clean_Data!$F$2:$F$101,Clean_Data!$H$2:$H$101,"Valid",Clean_Data!$C$2:$C$101,$H19,Clean_Data!$D$2:$D$101,J$18) | K19: =SUMIFS(Clean_Data!$F$2:$F$101,Clean_Data!$H$2:$H$101,"Valid",Clean_Data!$C$2:$C$101,$H19,Clean_Data!$D$2:$D$101,K$18) | L19: =SUMIFS(Clean_Data!$F$2:$F$101,Clean_Data!$H$2:$H$101,"Valid",Clean_Data!$C$2:$C$101,$H19,Clean_Data!$D$2:$D$101,L$18) | M19: =SUMIFS(Clean_Data!$F$2:$F$101,Clean_Data!$H$2:$H$101,"Valid",Clean_Data!$C$2:$C$101,$H19,Clean_Data!$D$2:$D$101,M$18) | N19: =SUM(I19:M19)
H20: East | I20: =SUMIFS(Clean_Data!$F$2:$F$101,Clean_Data!$H$2:$H$101,"Valid",Clean_Data!$C$2:$C$101,$H20,Clean_Data!$D$2:$D$101,I$18) | J20: =SUMIFS(Clean_Data!$F$2:$F$101,Clean_Data!$H$2:$H$101,"Valid",Clean_Data!$C$2:$C$101,$H20,Clean_Data!$D$2:$D$101,J$18) | K20: =SUMIFS(Clean_Data!$F$2:$F$101,Clean_Data!$H$2:$H$101,"Valid",Clean_Data!$C$2:$C$101,$H20,Clean_Data!$D$2:$D$101,K$18) | L20: =SUMIFS(Clean_Data!$F$2:$F$101,Clean_Data!$H$2:$H$101,"Valid",Clean_Data!$C$2:$C$101,$H20,Clean_Data!$D$2:$D$101,L$18) | M20: =SUMIFS(Clean_Data!$F$2:$F$101,Clean_Data!$H$2:$H$101,"Valid",Clean_Data!$C$2:$C$101,$H20,Clean_Data!$D$2:$D$101,M$18) | N20: =SUM(I20:M20)
H21: North | I21: =SUMIFS(Clean_Data!$F$2:$F$101,Clean_Data!$H$2:$H$101,"Valid",Clean_Data!$C$2:$C$101,$H21,Clean_Data!$D$2:$D$101,I$18) | J21: =SUMIFS(Clean_Data!$F$2:$F$101,Clean_Data!$H$2:$H$101,"Valid",Clean_Data!$C$2:$C$101,$H21,Clean_Data!$D$2:$D$101,J$18) | K21: =SUMIFS(Clean_Data!$F$2:$F$101,Clean_Data!$H$2:$H$101,"Valid",Clean_Data!$C$2:$C$101,$H21,Clean_Data!$D$2:$D$101,K$18) | L21: =SUMIFS(Clean_Data!$F$2:$F$101,Clean_Data!$H$2:$H$101,"Valid",Clean_Data!$C$2:$C$101,$H21,Clean_Data!$D$2:$D$101,L$18) | M21: =SUMIFS(Clean_Data!$F$2:$F$101,Clean_Data!$H$2:$H$101,"Valid",Clean_Data!$C$2:$C$101,$H21,Clean_Data!$D$2:$D$101,M$18) | N21: =SUM(I21:M21)
H22: South | I22: =SUMIFS(Clean_Data!$F$2:$F$101,Clean_Data!$H$2:$H$101,"Valid",Clean_Data!$C$2:$C$101,$H22,Clean_Data!$D$2:$D$101,I$18) | J22: =SUMIFS(Clean_Data!$F$2:$F$101,Clean_Data!$H$2:$H$101,"Valid",Clean_Data!$C$2:$C$101,$H22,Clean_Data!$D$2:$D$101,J$18) | K22: =SUMIFS(Clean_Data!$F$2:$F$101,Clean_Data!$H$2:$H$101,"Valid",Clean_Data!$C$2:$C$101,$H22,Clean_Data!$D$2:$D$101,K$18) | L22: =SUMIFS(Clean_Data!$F$2:$F$101,Clean_Data!$H$2:$H$101,"Valid",Clean_Data!$C$2:$C$101,$H22,Clean_Data!$D$2:$D$101,L$18) | M22: =SUMIFS(Clean_Data!$F$2:$F$101,Clean_Data!$H$2:$H$101,"Valid",Clean_Data!$C$2:$C$101,$H22,Clean_Data!$D$2:$D$101,M$18) | N22: =SUM(I22:M22)
H23: West | I23: =SUMIFS(Clean_Data!$F$2:$F$101,Clean_Data!$H$2:$H$101,"Valid",Clean_Data!$C$2:$C$101,$H23,Clean_Data!$D$2:$D$101,I$18) | J23: =SUMIFS(Clean_Data!$F$2:$F$101,Clean_Data!$H$2:$H$101,"Valid",Clean_Data!$C$2:$C$101,$H23,Clean_Data!$D$2:$D$101,J$18) | K23: =SUMIFS(Clean_Data!$F$2:$F$101,Clean_Data!$H$2:$H$101,"Valid",Clean_Data!$C$2:$C$101,$H23,Clean_Data!$D$2:$D$101,K$18) | L23: =SUMIFS(Clean_Data!$F$2:$F$101,Clean_Data!$H$2:$H$101,"Valid",Clean_Data!$C$2:$C$101,$H23,Clean_Data!$D$2:$D$101,L$18) | M23: =SUMIFS(Clean_Data!$F$2:$F$101,Clean_Data!$H$2:$H$101,"Valid",Clean_Data!$C$2:$C$101,$H23,Clean_Data!$D$2:$D$101,M$18) | N23: =SUM(I23:M23)
H24: Total | I24: =SUM(I19:I23) | J24: =SUM(J19:J23) | K24: =SUM(K19:K23) | L24: =SUM(L19:L23) | M24: =SUM(M19:M23) | N24: =SUM(N19:N23)

Sheet Chart_Data
A1: Chart Data (Dashboard filters नुसार आपोआप बदलतो) - हे बदलू नका
A2: Region criteria | B2: =IF(Dashboard!B8="All","*",Dashboard!B8)
A3: Category criteria | B3: =IF(Dashboard!B11="All","*",Dashboard!B11)
A4: Month criteria | B4: =IF(Dashboard!B14="All","*",Dashboard!B14)
A7: Region | B7: Revenue | D7: Category | E7: Revenue | G7: Month | H7: Revenue | J7: Quarter | K7: Revenue
A8: Central | B8: =SUMIFS(Clean_Data!$F$2:$F$101,Clean_Data!$H$2:$H$101,"Valid",Clean_Data!$D$2:$D$101,$B$3,Clean_Data!$G$2:$G$101,$B$4,Clean_Data!$C$2:$C$101,A8) | D8: Electronics | E8: =SUMIFS(Clean_Data!$F$2:$F$101,Clean_Data!$H$2:$H$101,"Valid",Clean_Data!$C$2:$C$101,$B$2,Clean_Data!$G$2:$G$101,$B$4,Clean_Data!$D$2:$D$101,D8) | G8: Jan | H8: =SUMIFS(Clean_Data!$F$2:$F$101,Clean_Data!$H$2:$H$101,"Valid",Clean_Data!$C$2:$C$101,$B$2,Clean_Data!$D$2:$D$101,$B$3,Clean_Data!$G$2:$G$101,G8) | J8: Q1 (Jan-Mar) | K8: =SUM(H8:H10)
A9: East | B9: =SUMIFS(Clean_Data!$F$2:$F$101,Clean_Data!$H$2:$H$101,"Valid",Clean_Data!$D$2:$D$101,$B$3,Clean_Data!$G$2:$G$101,$B$4,Clean_Data!$C$2:$C$101,A9) | D9: Fashion | E9: =SUMIFS(Clean_Data!$F$2:$F$101,Clean_Data!$H$2:$H$101,"Valid",Clean_Data!$C$2:$C$101,$B$2,Clean_Data!$G$2:$G$101,$B$4,Clean_Data!$D$2:$D$101,D9) | G9: Feb | H9: =SUMIFS(Clean_Data!$F$2:$F$101,Clean_Data!$H$2:$H$101,"Valid",Clean_Data!$C$2:$C$101,$B$2,Clean_Data!$D$2:$D$101,$B$3,Clean_Data!$G$2:$G$101,G9) | J9: Q2 (Apr-Jun) | K9: =SUM(H11:H13)
A10: North | B10: =SUMIFS(Clean_Data!$F$2:$F$101,Clean_Data!$H$2:$H$101,"Valid",Clean_Data!$D$2:$D$101,$B$3,Clean_Data!$G$2:$G$101,$B$4,Clean_Data!$C$2:$C$101,A10) | D10: Home Decor | E10: =SUMIFS(Clean_Data!$F$2:$F$101,Clean_Data!$H$2:$H$101,"Valid",Clean_Data!$C$2:$C$101,$B$2,Clean_Data!$G$2:$G$101,$B$4,Clean_Data!$D$2:$D$101,D10) | G10: Mar | H10: =SUMIFS(Clean_Data!$F$2:$F$101,Clean_Data!$H$2:$H$101,"Valid",Clean_Data!$C$2:$C$101,$B$2,Clean_Data!$D$2:$D$101,$B$3,Clean_Data!$G$2:$G$101,G10) | J10: Q3 (Jul-Sep) | K10: =SUM(H14:H16)
A11: South | B11: =SUMIFS(Clean_Data!$F$2:$F$101,Clean_Data!$H$2:$H$101,"Valid",Clean_Data!$D$2:$D$101,$B$3,Clean_Data!$G$2:$G$101,$B$4,Clean_Data!$C$2:$C$101,A11) | D11: Beauty | E11: =SUMIFS(Clean_Data!$F$2:$F$101,Clean_Data!$H$2:$H$101,"Valid",Clean_Data!$C$2:$C$101,$B$2,Clean_Data!$G$2:$G$101,$B$4,Clean_Data!$D$2:$D$101,D11) | G11: Apr | H11: =SUMIFS(Clean_Data!$F$2:$F$101,Clean_Data!$H$2:$H$101,"Valid",Clean_Data!$C$2:$C$101,$B$2,Clean_Data!$D$2:$D$101,$B$3,Clean_Data!$G$2:$G$101,G11)
A12: West | B12: =SUMIFS(Clean_Data!$F$2:$F$101,Clean_Data!$H$2:$H$101,"Valid",Clean_Data!$D$2:$D$101,$B$3,Clean_Data!$G$2:$G$101,$B$4,Clean_Data!$C$2:$C$101,A12) | D12: Sports | E12: =SUMIFS(Clean_Data!$F$2:$F$101,Clean_Data!$H$2:$H$101,"Valid",Clean_Data!$C$2:$C$101,$B$2,Clean_Data!$G$2:$G$101,$B$4,Clean_Data!$D$2:$D$101,D12) | G12: May | H12: =SUMIFS(Clean_Data!$F$2:$F$101,Clean_Data!$H$2:$H$101,"Valid",Clean_Data!$C$2:$C$101,$B$2,Clean_Data!$D$2:$D$101,$B$3,Clean_Data!$G$2:$G$101,G12)
G13: Jun | H13: =SUMIFS(Clean_Data!$F$2:$F$101,Clean_Data!$H$2:$H$101,"Valid",Clean_Data!$C$2:$C$101,$B$2,Clean_Data!$D$2:$D$101,$B$3,Clean_Data!$G$2:$G$101,G13)
G14: Jul | H14: =SUMIFS(Clean_Data!$F$2:$F$101,Clean_Data!$H$2:$H$101,"Valid",Clean_Data!$C$2:$C$101,$B$2,Clean_Data!$D$2:$D$101,$B$3,Clean_Data!$G$2:$G$101,G14)
G15: Aug | H15: =SUMIFS(Clean_Data!$F$2:$F$101,Clean_Data!$H$2:$H$101,"Valid",Clean_Data!$C$2:$C$101,$B$2,Clean_Data!$D$2:$D$101,$B$3,Clean_Data!$G$2:$G$101,G15)
G16: Sep | H16: =SUMIFS(Clean_Data!$F$2:$F$101,Clean_Data!$H$2:$H$101,"Valid",Clean_Data!$C$2:$C$101,$B$2,Clean_Data!$D$2:$D$101,$B$3,Clean_Data!$G$2:$G$101,G16)
